Workbook

Sheet （様式2-2）参画事業者一覧
A1: 第３回公募 小規模事業者持続化補助金＜共同・協業型＞ | AL1: （様式2-2）
A2: 参画事業者一覧
A3: 申請者名 | AP3: 参画事業者比率
A5: 展示会・商談会の取組に参加する全ての事業者数 | K5: ▶（うち参画事業者の要件を満たす事業者） | P5: =COUNTIF(B32:B131,"✓") -> 0 | R5: 者 | T5: ▶ | U5: （ | V5: =COUNTIFS(B32:B131,"✓",AM32:AM131,"✓") -> 0 | X5: 者 | Y5: ） | Z5: =IF(AND(P5<>0,V5<5),"※ 参画事業者が5者未満の取組は申請することができません。","") | AP5: =IFERROR(V5/P5,0) -> 0
A6: 催事販売の取組に参加する全ての事業者数 | K6: ▶（うち参画事業者の要件を満たす事業者） | P6: =COUNTIF(C32:C131,"✓") -> 0 | R6: 者 | T6: ▶ | U6: （ | V6: =COUNTIFS(C32:C131,"✓",AM32:AM131,"✓") -> 0 | X6: 者 | Y6: ） | Z6: =IF(AND(P6<>0,V6<5),"※ 参画事業者が5者未満の取組は申請することができません。","") | AP6: =IFERROR(V6/P6,0) -> 0
A7: 販売拠点構築の取組に参加する全ての事業者数 | K7: ▶（うち参画事業者の要件を満たす事業者） | P7: =COUNTIF(D32:D131,"✓") -> 0 | R7: 者 | T7: ▶ | U7: （ | V7: =COUNTIFS(D32:D131,"✓",AM32:AM131,"✓") -> 0 | X7: 者 | Y7: ） | Z7: =IF(AND(P7<>0,V7<5),"※ 参画事業者が5者未満の取組は申請することができません。","") | AP7: =IFERROR(V7/P7,0) -> 0
A9: ※参画事業者の要件については公募要領を参照。
A10: [参画事業者一覧]
A11: ※個人事業主の法人番号欄及び資本金欄は「0（ゼロ）」を記入する。
A12: ※事業者数が多く行が足りない場合は、事務局まで連絡すること。申請者が様式を変更してはならない。
A13: ※記載内容に不備がある場合は、参画事業者としては認められない。参画事業者は「商工業者」とする。
A14: ※業種は公募要領「別添3：小規模事業者について」を参照。
A15: ※従業員については、常時使用する従業員数を記入する。
A16: ※補助金事務局より、記載内容について問合せを行う場合がある。
A18: 参画事業者に係る確認事項：参画事業者の要件に合致しているか確認し、次の項目にチェックをつける。
A19: ※次の①～⑦のいずれかに該当する事業者は、小規模事業者であっても参画事業者とはなりえないため、該当事業者の要件（AM列）を「-」に上書すること。
A20: ①法人の参画事業者が対象 資本金または出資金が5億円以上の法人に直接または間接に100％の株式を保有されている。 | Q20: 全事業者が該当しない | Y20: 該当する事業者がいる | AF20: =IF(OR(AND(P20="",X20=""),AND(P20<>"",X20<>"")),"←いずれかの該当する項目を選択","") -> ←いずれかの該当する項目を選択
A21: ②全参画事業者が対象 直近過去3年分の各年または各事業年度の課税所得の年平均額が15億円を超えている。 | Q21: 全事業者が該当しない | Y21: 該当する事業者がいる | AF21: =IF(OR(AND(P21="",X21=""),AND(P21<>"",X21<>"")),"←いずれかの該当する項目を選択","") -> ←いずれかの該当する項目を選択
A22: ③法人の参画事業者が対象 申請者と子会社等の資本関係を有している。 | Q22: 全事業者が該当しない | Y22: 該当する事業者がいる | AF22: =IF(OR(AND(P22="",X22=""),AND(P22<>"",X22<>"")),"←いずれかの該当する項目を選択","") -> ←いずれかの該当する項目を選択
A23: ④法人の参画事業者が対象 申請者が会社及び会社に準ずる営利法人であって、申請者の役員が参画事業者の役員を兼任している。 | Q23: 全事業者が該当しない | Y23: 該当する事業者がいる | AF23: =IF(OR(AND(P23="",X23=""),AND(P23<>"",X23<>"")),"←いずれかの該当する項目を選択","") -> ←いずれかの該当する項目を選択
A24: ⑤全参画事業者が対象 一つの申請回で、複数の補助事業に参画している。 | Q24: 全事業者が該当しない | Y24: 該当する事業者がいる | AF24: =IF(OR(AND(P24="",X24=""),AND(P24<>"",X24<>"")),"←いずれかの該当する項目を選択","") -> ←いずれかの該当する項目を選択
A25: ⑥全参画事業者が対象 公募要領：参画事業者（小規模事業者）の定義における参画事業者の範囲の参画事業者とならない者に該当している。 | Q25: 全事業者が該当しない | Y25: 該当する事業者がいる | AF25: =IF(OR(AND(P25="",X25=""),AND(P25<>"",X25<>"")),"←いずれかの該当する項目を選択","") -> ←いずれかの該当する項目を選択
A26: ⑦全参画事業者が対象 第３回公募申請時点で実施中の小規模事業者持続化補助金 ＜共同・協業型＞にかかる補助事業に参画している。 | Q26: 全事業者が該当しない | Y26: 該当する事業者がいる | AF26: =IF(OR(AND(P26="",X26=""),AND(P26<>"",X26<>"")),"←いずれかの該当する項目を選択","") -> ←いずれかの該当する項目を選択
A27: ※ 参画事業者の要件を満たさない事業者も記入すること
A28: ※ 複数の取組に重複して参画する事業者は複数の取組(B～D列)で「✓」を選択すること
A29: ※ 取組は右記のとおりに略す：展示会・商談会の取組→展、催事販売の取組→催、販売拠点構築の取組→販
A30: 番号 | B30: 取組 ※ | E30: 事業者名 ※略称不可 | K30: 法人番号 | O30: 本社所在地 （個人事業主は事業所の所在地） | R30: 業種 | V30: 資本金 （円） | X30: 従業員数 （人） | Z30: 売上高 （円） | AB30: 補助事業で取り扱う 商材・サービス等 | AF30: 代表者氏名 | AI30: 代表者電話番号 | AM30: 参画事業者の要件
B31: 展 | C31: 催 | D31: 販 | AS31: 小規模事業者判定
A32: 1 | AM32: =IF(OR(X32="",AS32=""),"",IF($AS32="ok","✓","-")) | AP32: =IF(2<=COUNTIF(E:E,E32),"・事業者名：重複"&COUNTIF(E:E,E32)&"行","")&IF(AND(E32<>"",R32=""),"・業種：未選択","")&IF(AND(E32<>"",X32=""),"・従業員数：未入力","") | AS32: =IF($AT32="","",IF(AND($AT32=$AV$34,$X32<6),"ok",IF(AND($AT32=$AV$35,$X32<21),"ok",IF(AND($AT32=$AV$36,$X32<21),"ok")))) | AT32: =IF($R32="","",IF($R32=$AW$34,$AV$34,IF($R32=$AW$35,$AV$35,$AV$36))) | AW32: 小規模事業者
A33: 2 | AM33: =IF(OR(X33="",AS33=""),"",IF($AS33="ok","✓","-")) | AP33: =IF(2<=COUNTIF(E:E,E33),"・事業者名：重複"&COUNTIF(E:E,E33)&"行","")&IF(AND(E33<>"",R33=""),"・業種：未選択","")&IF(AND(E33<>"",X33=""),"・従業員数：未入力","") | AS33: =IF($AT33="","",IF(AND($AT33=$AV$34,$X33<6),"ok",IF(AND($AT33=$AV$35,$X33<21),"ok",IF(AND($AT33=$AV$36,$X33<21),"ok")))) | AT33: =IF($R33="","",IF($R33=$AW$34,$AV$34,IF($R33=$AW$35,$AV$35,$AV$36))) | AW33: 業種 | AY33: 常時使用する従業員の数※
A34: 3 | AM34: =IF(OR(X34="",AS34=""),"",IF($AS34="ok","✓","-")) | AP34: =IF(2<=COUNTIF(E:E,E34),"・事業者名：重複"&COUNTIF(E:E,E34)&"行","")&IF(AND(E34<>"",R34=""),"・業種：未選択","")&IF(AND(E34<>"",X34=""),"・従業員数：未入力","") | AS34: =IF($AT34="","",IF(AND($AT34=$AV$34,$X34<6),"ok",IF(AND($AT34=$AV$35,$X34<21),"ok",IF(AND($AT34=$AV$36,$X34<21),"ok")))) | AT34: =IF($R34="","",IF($R34=$AW$34,$AV$34,IF($R34=$AW$35,$AV$35,$AV$36))) | AV34: ① | AW34: 商業・サービス業（宿泊業・娯楽業除く） | AY34: ５人以下
A35: 4 | AM35: =IF(OR(X35="",AS35=""),"",IF($AS35="ok","✓","-")) | AP35: =IF(2<=COUNTIF(E:E,E35),"・事業者名：重複"&COUNTIF(E:E,E35)&"行","")&IF(AND(E35<>"",R35=""),"・業種：未選択","")&IF(AND(E35<>"",X35=""),"・従業員数：未入力","") | AS35: =IF($AT35="","",IF(AND($AT35=$AV$34,$X35<6),"ok",IF(AND($AT35=$AV$35,$X35<21),"ok",IF(AND($AT35=$AV$36,$X35<21),"ok")))) | AT35: =IF($R35="","",IF($R35=$AW$34,$AV$34,IF($R35=$AW$35,$AV$35,$AV$36))) | AV35: ② | AW35: サービス業のうち宿泊業・娯楽業 | AY35: ２０人以下
A36: 5 | AM36: =IF(OR(X36="",AS36=""),"",IF($AS36="ok","✓","-")) | AP36: =IF(2<=COUNTIF(E:E,E36),"・事業者名：重複"&COUNTIF(E:E,E36)&"行","")&IF(AND(E36<>"",R36=""),"・業種：未選択","")&IF(AND(E36<>"",X36=""),"・従業員数：未入力","") | AS36: =IF($AT36="","",IF(AND($AT36=$AV$34,$X36<6),"ok",IF(AND($AT36=$AV$35,$X36<21),"ok",IF(AND($AT36=$AV$36,$X36<21),"ok")))) | AT36: =IF($R36="","",IF($R36=$AW$34,$AV$34,IF($R36=$AW$35,$AV$35,$AV$36))) | AV36: ③ | AW36: 製造業その他 | AY36: ２０人以下
A37: 6 | AM37: =IF(OR(X37="",AS37=""),"",IF($AS37="ok","✓","-")) | AP37: =IF(2<=COUNTIF(E:E,E37),"・事業者名：重複"&COUNTIF(E:E,E37)&"行","")&IF(AND(E37<>"",R37=""),"・業種：未選択","")&IF(AND(E37<>"",X37=""),"・従業員数：未入力","") | AS37: =IF($AT37="","",IF(AND($AT37=$AV$34,$X37<6),"ok",IF(AND($AT37=$AV$35,$X37<21),"ok",IF(AND($AT37=$AV$36,$X37<21),"ok")))) | AT37: =IF($R37="","",IF($R37=$AW$34,$AV$34,IF($R37=$AW$35,$AV$35,$AV$36)))
A38: 7 | AM38: =IF(OR(X38="",AS38=""),"",IF($AS38="ok","✓","-")) | AP38: =IF(2<=COUNTIF(E:E,E38),"・事業者名：重複"&COUNTIF(E:E,E38)&"行","")&IF(AND(E38<>"",R38=""),"・業種：未選択","")&IF(AND(E38<>"",X38=""),"・従業員数：未入力","") | AS38: =IF($AT38="","",IF(AND($AT38=$AV$34,$X38<6),"ok",IF(AND($AT38=$AV$35,$X38<21),"ok",IF(AND($AT38=$AV$36,$X38<21),"ok")))) | AT38: =IF($R38="","",IF($R38=$AW$34,$AV$34,IF($R38=$AW$35,$AV$35,$AV$36)))
A39: 8 | AM39: =IF(OR(X39="",AS39=""),"",IF($AS39="ok","✓","-")) | AP39: =IF(2<=COUNTIF(E:E,E39),"・事業者名：重複"&COUNTIF(E:E,E39)&"行","")&IF(AND(E39<>"",R39=""),"・業種：未選択","")&IF(AND(E39<>"",X39=""),"・従業員数：未入力","") | AS39: =IF($AT39="","",IF(AND($AT39=$AV$34,$X39<6),"ok",IF(AND($AT39=$AV$35,$X39<21),"ok",IF(AND($AT39=$AV$36,$X39<21),"ok")))) | AT39: =IF($R39="","",IF($R39=$AW$34,$AV$34,IF($R39=$AW$35,$AV$35,$AV$36)))
A40: 9 | AM40: =IF(OR(X40="",AS40=""),"",IF($AS40="ok","✓","-")) | AP40: =IF(2<=COUNTIF(E:E,E40),"・事業者名：重複"&COUNTIF(E:E,E40)&"行","")&IF(AND(E40<>"",R40=""),"・業種：未選択","")&IF(AND(E40<>"",X40=""),"・従業員数：未入力","") | AS40: =IF($AT40="","",IF(AND($AT40=$AV$34,$X40<6),"ok",IF(AND($AT40=$AV$35,$X40<21),"ok",IF(AND($AT40=$AV$36,$X40<21),"ok")))) | AT40: =IF($R40="","",IF($R40=$AW$34,$AV$34,IF($R40=$AW$35,$AV$35,$AV$36)))
A41: 10 | AM41: =IF(OR(X41="",AS41=""),"",IF($AS41="ok","✓","-")) | AP41: =IF(2<=COUNTIF(E:E,E41),"・事業者名：重複"&COUNTIF(E:E,E41)&"行","")&IF(AND(E41<>"",R41=""),"・業種：未選択","")&IF(AND(E41<>"",X41=""),"・従業員数：未入力","") | AS41: =IF($AT41="","",IF(AND($AT41=$AV$34,$X41<6),"ok",IF(AND($AT41=$AV$35,$X41<21),"ok",IF(AND($AT41=$AV$36,$X41<21),"ok")))) | AT41: =IF($R41="","",IF($R41=$AW$34,$AV$34,IF($R41=$AW$35,$AV$35,$AV$36)))
A42: 11 | AM42: =IF(OR(X42="",AS42=""),"",IF($AS42="ok","✓","-")) | AP42: =IF(2<=COUNTIF(E:E,E42),"・事業者名：重複"&COUNTIF(E:E,E42)&"行","")&IF(AND(E42<>"",R42=""),"・業種：未選択","")&IF(AND(E42<>"",X42=""),"・従業員数：未入力","") | AS42: =IF($AT42="","",IF(AND($AT42=$AV$34,$X42<6),"ok",IF(AND($AT42=$AV$35,$X42<21),"ok",IF(AND($AT42=$AV$36,$X42<21),"ok")))) | AT42: =IF($R42="","",IF($R42=$AW$34,$AV$34,IF($R42=$AW$35,$AV$35,$AV$36)))
A43: 12 | AM43: =IF(OR(X43="",AS43=""),"",IF($AS43="ok","✓","-")) | AP43: =IF(2<=COUNTIF(E:E,E43),"・事業者名：重複"&COUNTIF(E:E,E43)&"行","")&IF(AND(E43<>"",R43=""),"・業種：未選択","")&IF(AND(E43<>"",X43=""),"・従業員数：未入力","") | AS43: =IF($AT43="","",IF(AND($AT43=$AV$34,$X43<6),"ok",IF(AND($AT43=$AV$35,$X43<21),"ok",IF(AND($AT43=$AV$36,$X43<21),"ok")))) | AT43: =IF($R43="","",IF($R43=$AW$34,$AV$34,IF($R43=$AW$35,$AV$35,$AV$36)))
...

Sheet （別添）申請者との関係
A1: 参画事業者一覧 | I1: （様式2-2 ）参画事業者一覧 別添
A3: 申請者名 | H3: =IF('（様式2-2）参画事業者一覧'!$H3="","",'（様式2-2）参画事業者一覧'!$H3)
A5: ※「申請者との関係」には、これまでの申請者との関係や、申請者が実施する補助事業に参画するに至った経緯を記載する。
A6: ※「参画する理由・目標」には、補助事業に参画する理由や補助事業での目標を記載する。
A7: 番号 | B7: 事業者名 ※略称不可 | H7: 申請者との関係 | I7: 参画する理由・目標
A8: 1 | B8: =IF('（様式2-2）参画事業者一覧'!$E32="","",'（様式2-2）参画事業者一覧'!$E32)
A9: 2 | B9: =IF('（様式2-2）参画事業者一覧'!$E33="","",'（様式2-2）参画事業者一覧'!$E33)
A10: 3 | B10: =IF('（様式2-2）参画事業者一覧'!$E34="","",'（様式2-2）参画事業者一覧'!$E34)
A11: 4 | B11: =IF('（様式2-2）参画事業者一覧'!$E35="","",'（様式2-2）参画事業者一覧'!$E35)
A12: 5 | B12: =IF('（様式2-2）参画事業者一覧'!$E36="","",'（様式2-2）参画事業者一覧'!$E36)
A13: 6 | B13: =IF('（様式2-2）参画事業者一覧'!$E37="","",'（様式2-2）参画事業者一覧'!$E37)
A14: 7 | B14: =IF('（様式2-2）参画事業者一覧'!$E38="","",'（様式2-2）参画事業者一覧'!$E38)
A15: 8 | B15: =IF('（様式2-2）参画事業者一覧'!$E39="","",'（様式2-2）参画事業者一覧'!$E39)
A16: 9 | B16: =IF('（様式2-2）参画事業者一覧'!$E40="","",'（様式2-2）参画事業者一覧'!$E40)
A17: 10 | B17: =IF('（様式2-2）参画事業者一覧'!$E41="","",'（様式2-2）参画事業者一覧'!$E41)
A18: 11 | B18: =IF('（様式2-2）参画事業者一覧'!$E42="","",'（様式2-2）参画事業者一覧'!$E42)
A19: 12 | B19: =IF('（様式2-2）参画事業者一覧'!$E43="","",'（様式2-2）参画事業者一覧'!$E43)
... A107: 100 | B107: =IF('（様式2-2）参画事業者一覧'!$E131="","",'（様式2-2）参画事業者一覧'!$E131)
